{
 "cells": [
  {
   "cell_type": "markdown",
   "id": "0ab0f762-0327-4b0a-b567-08e21be973bb",
   "metadata": {},
   "source": [
    "Plot CWOP correlation data\n",
    "---"
   ]
  },
  {
   "cell_type": "code",
   "execution_count": 4,
   "id": "c523adc5-9962-46f3-8245-a445f489b21d",
   "metadata": {},
   "outputs": [
    {
     "ename": "ModuleNotFoundError",
     "evalue": "No module named 'geopandas'",
     "output_type": "error",
     "traceback": [
      "\u001b[0;31m---------------------------------------------------------------------------\u001b[0m",
      "\u001b[0;31mModuleNotFoundError\u001b[0m                       Traceback (most recent call last)",
      "Cell \u001b[0;32mIn[4], line 1\u001b[0m\n\u001b[0;32m----> 1\u001b[0m \u001b[38;5;28;01mimport\u001b[39;00m \u001b[38;5;21;01mgeopandas\u001b[39;00m \u001b[38;5;28;01mas\u001b[39;00m \u001b[38;5;21;01mgpd\u001b[39;00m\n\u001b[1;32m      2\u001b[0m \u001b[38;5;28;01mimport\u001b[39;00m \u001b[38;5;21;01mpandas\u001b[39;00m \u001b[38;5;28;01mas\u001b[39;00m \u001b[38;5;21;01mpd\u001b[39;00m\n\u001b[1;32m      3\u001b[0m \u001b[38;5;28;01mimport\u001b[39;00m \u001b[38;5;21;01mos\u001b[39;00m\n",
      "\u001b[0;31mModuleNotFoundError\u001b[0m: No module named 'geopandas'"
     ]
    }
   ],
   "source": [
    "import geopandas as gpd\n",
    "import pandas as pd\n",
    "import os\n",
    "from numpy import intersect1d\n",
    "import matplotlib.pyplot as plt\n",
    "\n",
    "correlations = pd.read_csv('../nearby_station_correlations.csv')\n",
    "correlations.info()\n",
    "correlations.head()"
   ]
  },
  {
   "cell_type": "code",
   "execution_count": 3,
   "id": "bf498f66-8b95-4d1d-bb44-37e81e3bb6b9",
   "metadata": {},
   "outputs": [
    {
     "name": "stdout",
     "output_type": "stream",
     "text": [
      "Collecting geopandas\n",
      "  Downloading geopandas-1.0.1-py3-none-any.whl.metadata (2.2 kB)\n",
      "Requirement already satisfied: numpy>=1.22 in /Library/Frameworks/Python.framework/Versions/3.12/lib/python3.12/site-packages (from geopandas) (2.1.1)\n",
      "Collecting pyogrio>=0.7.2 (from geopandas)\n",
      "  Downloading pyogrio-0.10.0.tar.gz (281 kB)\n",
      "  Installing build dependencies ... \u001b[?25ldone\n",
      "\u001b[?25h  Getting requirements to build wheel ... \u001b[?25ldone\n",
      "\u001b[?25h  Preparing metadata (pyproject.toml) ... \u001b[?25lerror\n",
      "  \u001b[1;31merror\u001b[0m: \u001b[1msubprocess-exited-with-error\u001b[0m\n",
      "  \n",
      "  \u001b[31m×\u001b[0m \u001b[32mPreparing metadata \u001b[0m\u001b[1;32m(\u001b[0m\u001b[32mpyproject.toml\u001b[0m\u001b[1;32m)\u001b[0m did not run successfully.\n",
      "  \u001b[31m│\u001b[0m exit code: \u001b[1;36m1\u001b[0m\n",
      "  \u001b[31m╰─>\u001b[0m \u001b[31m[28 lines of output]\u001b[0m\n",
      "  \u001b[31m   \u001b[0m Traceback (most recent call last):\n",
      "  \u001b[31m   \u001b[0m   File \"/Library/Frameworks/Python.framework/Versions/3.12/lib/python3.12/site-packages/pip/_vendor/pyproject_hooks/_in_process/_in_process.py\", line 353, in <module>\n",
      "  \u001b[31m   \u001b[0m     main()\n",
      "  \u001b[31m   \u001b[0m   File \"/Library/Frameworks/Python.framework/Versions/3.12/lib/python3.12/site-packages/pip/_vendor/pyproject_hooks/_in_process/_in_process.py\", line 335, in main\n",
      "  \u001b[31m   \u001b[0m     json_out['return_val'] = hook(**hook_input['kwargs'])\n",
      "  \u001b[31m   \u001b[0m                              ^^^^^^^^^^^^^^^^^^^^^^^^^^^^\n",
      "  \u001b[31m   \u001b[0m   File \"/Library/Frameworks/Python.framework/Versions/3.12/lib/python3.12/site-packages/pip/_vendor/pyproject_hooks/_in_process/_in_process.py\", line 149, in prepare_metadata_for_build_wheel\n",
      "  \u001b[31m   \u001b[0m     return hook(metadata_directory, config_settings)\n",
      "  \u001b[31m   \u001b[0m            ^^^^^^^^^^^^^^^^^^^^^^^^^^^^^^^^^^^^^^^^^\n",
      "  \u001b[31m   \u001b[0m   File \"/private/var/folders/4l/8m5k564x79g8krtzg8h1h35m0000gp/T/pip-build-env-zaclhmcw/overlay/lib/python3.12/site-packages/setuptools/build_meta.py\", line 373, in prepare_metadata_for_build_wheel\n",
      "  \u001b[31m   \u001b[0m     self.run_setup()\n",
      "  \u001b[31m   \u001b[0m   File \"/private/var/folders/4l/8m5k564x79g8krtzg8h1h35m0000gp/T/pip-build-env-zaclhmcw/overlay/lib/python3.12/site-packages/setuptools/build_meta.py\", line 318, in run_setup\n",
      "  \u001b[31m   \u001b[0m     exec(code, locals())\n",
      "  \u001b[31m   \u001b[0m   File \"<string>\", line 154, in <module>\n",
      "  \u001b[31m   \u001b[0m   File \"<string>\", line 129, in get_gdal_config\n",
      "  \u001b[31m   \u001b[0m   File \"<string>\", line 85, in get_gdal_config\n",
      "  \u001b[31m   \u001b[0m   File \"<string>\", line 39, in read_response\n",
      "  \u001b[31m   \u001b[0m   File \"/Library/Frameworks/Python.framework/Versions/3.12/lib/python3.12/subprocess.py\", line 466, in check_output\n",
      "  \u001b[31m   \u001b[0m     return run(*popenargs, stdout=PIPE, timeout=timeout, check=True,\n",
      "  \u001b[31m   \u001b[0m            ^^^^^^^^^^^^^^^^^^^^^^^^^^^^^^^^^^^^^^^^^^^^^^^^^^^^^^^^^\n",
      "  \u001b[31m   \u001b[0m   File \"/Library/Frameworks/Python.framework/Versions/3.12/lib/python3.12/subprocess.py\", line 548, in run\n",
      "  \u001b[31m   \u001b[0m     with Popen(*popenargs, **kwargs) as process:\n",
      "  \u001b[31m   \u001b[0m          ^^^^^^^^^^^^^^^^^^^^^^^^^^^\n",
      "  \u001b[31m   \u001b[0m   File \"/Library/Frameworks/Python.framework/Versions/3.12/lib/python3.12/subprocess.py\", line 1026, in __init__\n",
      "  \u001b[31m   \u001b[0m     self._execute_child(args, executable, preexec_fn, close_fds,\n",
      "  \u001b[31m   \u001b[0m   File \"/Library/Frameworks/Python.framework/Versions/3.12/lib/python3.12/subprocess.py\", line 1955, in _execute_child\n",
      "  \u001b[31m   \u001b[0m     raise child_exception_type(errno_num, err_msg, err_filename)\n",
      "  \u001b[31m   \u001b[0m FileNotFoundError: [Errno 2] No such file or directory: 'gdal-config'\n",
      "  \u001b[31m   \u001b[0m \u001b[31m[end of output]\u001b[0m\n",
      "  \n",
      "  \u001b[1;35mnote\u001b[0m: This error originates from a subprocess, and is likely not a problem with pip.\n",
      "\u001b[1;31merror\u001b[0m: \u001b[1mmetadata-generation-failed\u001b[0m\n",
      "\n",
      "\u001b[31m×\u001b[0m Encountered error while generating package metadata.\n",
      "\u001b[31m╰─>\u001b[0m See above for output.\n",
      "\n",
      "\u001b[1;35mnote\u001b[0m: This is an issue with the package mentioned above, not pip.\n",
      "\u001b[1;36mhint\u001b[0m: See above for details.\n",
      "\u001b[?25h"
     ]
    }
   ],
   "source": [
    "!pip install geopandas"
   ]
  },
  {
   "cell_type": "code",
   "execution_count": null,
   "id": "04f3808f-b13e-44a9-816c-6426c4c2cf08",
   "metadata": {},
   "outputs": [],
   "source": []
  }
 ],
 "metadata": {
  "kernelspec": {
   "display_name": "Python 3 (ipykernel)",
   "language": "python",
   "name": "python3"
  },
  "language_info": {
   "codemirror_mode": {
    "name": "ipython",
    "version": 3
   },
   "file_extension": ".py",
   "mimetype": "text/x-python",
   "name": "python",
   "nbconvert_exporter": "python",
   "pygments_lexer": "ipython3",
   "version": "3.12.3"
  }
 },
 "nbformat": 4,
 "nbformat_minor": 5
}
